<?xml version="1.0" encoding="UTF-8"?>
<!--
  Author: Jimmy Da Silva
  Contributers: Kelsey Hawkins, Ajit Krisshna N L, Muhammad Asif Rana 

-->
<robot xmlns:xacro="http://ros.org/wiki/xacro">

   <property name="pi" value="3.14159265" />
   <property name="scale" value="0.001 0.001 0.001" />

   <!-- Inertia parameters -->
   <property name="rail_mass" value="50.0" />

   <!-- Kinematic model -->
   <property name="rail_lower_limit" value="0.05" />
   <property name="rail_upper_limit" value="3.45" />

   <!-- Collision model 
   <property name="table_collision_offset" value="0.135 0.81 0.935" />-->
   <property name="table_collision_offset" value="3.620 0.81 0.935" />

   <xacro:macro name="table_rail">

      <link name="table_link">
         <visual>
            <geometry>
               <mesh filename="package://excel_description/meshes/visual/tables+rail.dae"/>
            </geometry>
            <origin rpy="0.0 0.0 0.0" xyz="0.0 0.0 0.0" />
         </visual>
         <collision>
            <geometry>
              <box size="0.92 2.25 0.87" />
            </geometry>
            <origin xyz="0.46 1.125 0.435" rpy="0 0 0" />
         </collision>
         <collision>
            <geometry>
              <box size="3.97 0.92 0.87" />
            </geometry>
            <origin xyz="1.985 0.46 0.435" rpy="0 0 0" />
         </collision>
         <collision>
            <geometry>
              <box size="0.92 2.0 0.87" />
            </geometry>
            <origin xyz="3.5 1.0 0.435" rpy="0 0 0" />
         </collision>
         <collision>
            <geometry>
              <box size="0.92 0.64 1.34" />
            </geometry>
            <origin xyz="3.5 -0.04 0.67" rpy="0 0 0" />
         </collision>
         <collision>
            <geometry>
              <box size="3.9 0.124 0.065" />
            </geometry>
            <origin xyz="1.847 0.811 0.905" rpy="0 0 0" />
         </collision>
      </link>

      <joint name="table_rail_joint" type="prismatic">
         <parent link="table_link" />
         <child link="rail_link" />
         <origin rpy="0.0 0.0 ${pi}" xyz="${table_collision_offset}" />
         <axis xyz="1 0 0" />
         <limit effort="10.0" lower="${rail_lower_limit}" upper="${rail_upper_limit}" velocity="${pi}" />
         <dynamics damping="10" friction="0.1" />
      </joint>

      <link name="rail_link">
         <inertial>
            <mass value="${rail_mass}" />
            <inertia ixx="1.0" ixy="0.0" ixz="0.0" iyy="1.0" iyz="0.0" izz="1.0" />
         </inertial>
      </link>

      <joint name="rail_base_joint" type="fixed">
         <parent link="rail_link" />
         <child link="base_link" />
         <origin rpy="0.0 0.0 ${pi}" xyz="0.0 0.0 0.034" />
      </joint>

      <transmission name="rail_base_trans" type="pr2_mechanism_model/SimpleTransmission">
         <actuator name="rail_base_motor" />
         <joint name="rail_base_joint" />
         <mechanicalReduction>1</mechanicalReduction>
      </transmission>

      <gazebo reference="table_link">
         <material value="Gazebo/Blue " />
         <turnGravityOff>false</turnGravityOff>
      </gazebo>

   </xacro:macro>
</robot>
